<robot
  name="kubot25_pkgs">
  
  <link name="base_footprint"/>
  <joint name="base_joint" type="fixed">
    <parent link="base_footprint"/>
    <child link="base_link"/>
    <origin xyz="0 0 0" rpy="0 0 0"/>
  </joint>
  
  <link
    name="base_link">
    <inertial>
      <origin
        xyz="0.0031365 3.8801E-05 0.00019581"
        rpy="0 0 0" />
      <mass
        value="4.116" />
      <inertia
        ixx="0.018909"
        ixy="2.9E-06"
        ixz="0.00096137"
        iyy="0.011988"
        iyz="2.2E-07"
        izz="0.011296" />
    </inertial>
    <visual>
      <origin
        xyz="0 0 0"
        rpy="0 0 0" />
      <geometry>
        <mesh
          filename="package://kubot25_pkgs/meshes/base_link.STL" />
      </geometry>
      <material
        name="">
        <color
          rgba="1 1 1 1" />
      </material>
    </visual>
    <collision>
      <origin
        xyz="0 0 0"
        rpy="0 0 0" />
      <geometry>
        <mesh
          filename="package://kubot25_pkgs/meshes/base_link_collision.STL" />
      </geometry>
    </collision>
  </link>
  <link
    name="Neck_yaw">
    <inertial>
      <origin
        xyz="1.2504E-14 2.5464E-13 0.031083"
        rpy="0 0 0" />
      <mass
        value="0.03844" />
      <inertia
        ixx="1.819E-05"
        ixy="0"
        ixz="0"
        iyy="5.34E-06"
        iyz="0"
        izz="1.717E-05" />
    </inertial>
    <visual>
      <origin
        xyz="0 0 0"
        rpy="0 0 0" />
      <geometry>
        <mesh
          filename="package://kubot25_pkgs/meshes/Neck_yaw.STL" />
      </geometry>
      <material
        name="">
        <color
          rgba="1 1 1 1" />
      </material>
    </visual>
    <collision>
      <origin
        xyz="0 0 0"
        rpy="0 0 0" />
      <geometry>
        <mesh
          filename="package://kubot25_pkgs/meshes/Neck_yaw_collision.STL" />
      </geometry>
    </collision>
  </link>
  <joint
    name="Neck_yaw_joint"
    type="revolute">
    <origin
      xyz="0.037762 5.0186E-05 0.063694"
      rpy="0 0 0" />
    <parent
      link="base_link" />
    <child
      link="Neck_yaw" />
    <axis
      xyz="0 0 1" />
    <limit
      lower="-3.1415"
      upper="3.1415"
      effort="100.0"
      velocity="10.0" />
  </joint>
  <link
    name="Head_pitch">
    <inertial>
      <origin
        xyz="0.0016148 -0.00027502 0.047365"
        rpy="0 0 0" />
      <mass
        value="1.03932044" />
      <inertia
        ixx="0.0007601"
        ixy="3E-07"
        ixz="1.779E-05"
        iyy="0.00045786"
        iyz="-4.9E-07"
        izz="0.00035973" />
    </inertial>
    <visual>
      <origin
        xyz="0 0 0"
        rpy="0 0 0" />
      <geometry>
        <mesh
          filename="package://kubot25_pkgs/meshes/Head_pitch.STL" />
      </geometry>
      <material
        name="">
        <color
          rgba="1 1 1 1" />
      </material>
    </visual>
    <collision>
      <origin
        xyz="0 0 0"
        rpy="0 0 0" />
      <geometry>
        <mesh
          filename="package://kubot25_pkgs/meshes/Head_pitch_collision.STL" />
      </geometry>
    </collision>
  </link>
  <joint
    name="Head_pitch_joint"
    type="revolute">
    <origin
      xyz="0 0.000475 0.04825"
      rpy="0 0 0" />
    <parent
      link="Neck_yaw" />
    <child
      link="Head_pitch" />
    <axis
      xyz="0 -1 0" />
    <limit
      lower="-3.1415"
      upper="3.1415"
      effort="100.0"
      velocity="10.0" />
  </joint>
  <link
    name="L_Shoulder_pitch">
    <inertial>
      <origin
        xyz="9.0068E-10 0.031774 -0.0016022"
        rpy="0 0 0" />
      <mass
        value="0.00983" />
      <inertia
        ixx="1.39E-06"
        ixy="0"
        ixz="0"
        iyy="4.39E-06"
        iyz="-1.6E-07"
        izz="4.52E-06" />
    </inertial>
    <visual>
      <origin
        xyz="0 0 0"
        rpy="0 0 0" />
      <geometry>
        <mesh
          filename="package://kubot25_pkgs/meshes/L_Shoulder_pitch.STL" />
      </geometry>
      <material
        name="">
        <color
          rgba="1 1 1 1" />
      </material>
    </visual>
    <collision>
      <origin
        xyz="0 0 0"
        rpy="0 0 0" />
      <geometry>
        <mesh
          filename="package://kubot25_pkgs/meshes/L_Shoulder_pitch_collision.STL" />
      </geometry>
    </collision>
  </link>
  <joint
    name="L_Shoulder_pitch_joint"
    type="revolute">
    <origin
      xyz="0.037561 0.06255 0.059244"
      rpy="0 0 0" />
    <parent
      link="base_link" />
    <child
      link="L_Shoulder_pitch" />
    <axis
      xyz="0 1 0" />
    <limit
      lower="-3.1415"
      upper="3.1415"
      effort="100.0"
      velocity="10.0" />
  </joint>
  <link
    name="L_Arm_roll">
    <inertial>
      <origin
        xyz="3.3313E-05 3.3313E-05 -0.0406"
        rpy="0 0 0" />
      <mass
        value="1.63108" />
      <inertia
        ixx="0.00143237"
        ixy="0"
        ixz="1.12E-06"
        iyy="0.00143237"
        iyz="-1.12E-06"
        izz="3.071E-05" />
    </inertial>
    <visual>
      <origin
        xyz="0 0 0"
        rpy="0 0 0" />
      <geometry>
        <mesh
          filename="package://kubot25_pkgs/meshes/L_Arm_roll.STL" />
      </geometry>
      <material
        name="">
        <color
          rgba="1 1 1 1" />
      </material>
    </visual>
    <collision>
      <origin
        xyz="0 0 0"
        rpy="0 0 0" />
      <geometry>
        <mesh
          filename="package://kubot25_pkgs/meshes/L_Arm_roll_collision.STL" />
      </geometry>
    </collision>
  </link>
  <joint
    name="L_Arm_roll_joint"
    type="revolute">
    <origin
      xyz="-0.000475 0.047406 -0.01045"
      rpy="0 0 0" />
    <parent
      link="L_Shoulder_pitch" />
    <child
      link="L_Arm_roll" />
    <axis
      xyz="1 0 0" />
    <limit
      lower="-3.1415"
      upper="3.1415"
      effort="100.0"
      velocity="10.0" />
  </joint>
  <link
    name="L_Hand_pitch">
    <inertial>
      <origin
        xyz="1.6081E-11 2.1883E-09 -0.13605"
        rpy="0 0 0" />
      <mass
        value="0.06716" />
      <inertia
        ixx="0.00027857"
        ixy="0"
        ixz="0"
        iyy="0.00027829"
        iyz="0"
        izz="3.728E-05" />
    </inertial>
    <visual>
      <origin
        xyz="0 0 0"
        rpy="0 0 0" />
      <geometry>
        <mesh
          filename="package://kubot25_pkgs/meshes/L_Hand_pitch.STL" />
      </geometry>
      <material
        name="">
        <color
          rgba="1 1 1 1" />
      </material>
    </visual>
    <collision>
      <origin
        xyz="0 0 0"
        rpy="0 0 0" />
      <geometry>
        <mesh
          filename="package://kubot25_pkgs/meshes/L_Hand_pitch_collision.STL" />
      </geometry>
    </collision>
  </link>
  <joint
    name="L_Hand_pitch_joint"
    type="revolute">
    <origin
      xyz="0 0 -0.0812"
      rpy="0 0 0" />
    <parent
      link="L_Arm_roll" />
    <child
      link="L_Hand_pitch" />
    <axis
      xyz="0 1 0" />
    <limit
      lower="-3.1415"
      upper="3.1415"
      effort="100.0"
      velocity="10.0" />
  </joint>
  <link
    name="R_Shoulder_pitch">
    <inertial>
      <origin
        xyz="-4.4012E-10 -0.032976 -0.00078297"
        rpy="0 0 0" />
      <mass
        value="0.02530554" />
      <inertia
        ixx="4.02E-06"
        ixy="0"
        ixz="0"
        iyy="1.155E-05"
        iyz="1.4E-07"
        izz="1.268E-05" />
    </inertial>
    <visual>
      <origin
        xyz="0 0 0"
        rpy="0 0 0" />
      <geometry>
        <mesh
          filename="package://kubot25_pkgs/meshes/R_Shoulder_pitch.STL" />
      </geometry>
      <material
        name="">
        <color
          rgba="1 1 1 1" />
      </material>
    </visual>
    <collision>
      <origin
        xyz="0 0 0"
        rpy="0 0 0" />
      <geometry>
        <mesh
          filename="package://kubot25_pkgs/meshes/R_Shoulder_pitch_collision.STL" />
      </geometry>
    </collision>
  </link>
  <joint
    name="R_Shoulder_pitch_joint"
    type="revolute">
    <origin
      xyz="0.037561 -0.06245 0.059244"
      rpy="0 0 0" />
    <parent
      link="base_link" />
    <child
      link="R_Shoulder_pitch" />
    <axis
      xyz="0 -1 0" />
    <limit
      lower="-3.1415"
      upper="3.1415"
      effort="100.0"
      velocity="10.0" />
  </joint>
  <link
    name="R_Arm_roll">
    <inertial>
      <origin
        xyz="3.1647E-05 -3.1647E-05 -0.0406"
        rpy="0 0 0" />
      <mass
        value="1.63108" />
      <inertia
        ixx="0.00143237"
        ixy="0"
        ixz="1.22E-06"
        iyy="0.00143237"
        iyz="1.22E-06"
        izz="3.071E-05" />
    </inertial>
    <visual>
      <origin
        xyz="0 0 0"
        rpy="0 0 0" />
      <geometry>
        <mesh
          filename="package://kubot25_pkgs/meshes/R_Arm_roll.STL" />
      </geometry>
      <material
        name="">
        <color
          rgba="1 1 1 1" />
      </material>
    </visual>
    <collision>
      <origin
        xyz="0 0 0"
        rpy="0 0 0" />
      <geometry>
        <mesh
          filename="package://kubot25_pkgs/meshes/R_Arm_roll_collision.STL" />
      </geometry>
    </collision>
  </link>
  <joint
    name="R_Arm_roll_joint"
    type="revolute">
    <origin
      xyz="-0.000475 -0.047406 -0.01045"
      rpy="0 0 0" />
    <parent
      link="R_Shoulder_pitch" />
    <child
      link="R_Arm_roll" />
    <axis
      xyz="1 0 0" />
    <limit
      lower="-3.1415"
      upper="3.1415"
      effort="100.0"
      velocity="10.0" />
  </joint>
  <link
    name="R_Hand_pitch">
    <inertial>
      <origin
        xyz="1.6482E-11 2.1881E-09 -0.13605"
        rpy="0 0 0" />
      <mass
        value="0.06716" />
      <inertia
        ixx="0.00027857"
        ixy="0"
        ixz="0"
        iyy="0.00027829"
        iyz="0"
        izz="3.728E-05" />
    </inertial>
    <visual>
      <origin
        xyz="0 0 0"
        rpy="0 0 0" />
      <geometry>
        <mesh
          filename="package://kubot25_pkgs/meshes/R_Hand_pitch.STL" />
      </geometry>
      <material
        name="">
        <color
          rgba="1 1 1 1" />
      </material>
    </visual>
    <collision>
      <origin
        xyz="0 0 0"
        rpy="0 0 0" />
      <geometry>
        <mesh
          filename="package://kubot25_pkgs/meshes/R_Hand_pitch_collision.STL" />
      </geometry>
    </collision>
  </link>
  <joint
    name="R_Hand_pitch_joint"
    type="revolute">
    <origin
      xyz="0 0 -0.0812"
      rpy="0 0 0" />
    <parent
      link="R_Arm_roll" />
    <child
      link="R_Hand_pitch" />
    <axis
      xyz="0 -1 0" />
    <limit
      lower="-3.1415"
      upper="3.1415"
      effort="100.0"
      velocity="10.0" />
  </joint>
  <link
    name="L_Hip_yaw">
    <inertial>
      <origin
        xyz="-0.0014744 6.6613E-16 -0.039988"
        rpy="0 0 0" />
      <mass
        value="0.023559" />
      <inertia
        ixx="8.7E-06"
        ixy="0"
        ixz="-7.7E-07"
        iyy="1.842E-05"
        iyz="0"
        izz="1.691E-05" />
    </inertial>
    <visual>
      <origin
        xyz="0 0 0"
        rpy="0 0 0" />
      <geometry>
        <mesh
          filename="package://kubot25_pkgs/meshes/L_Hip_yaw.STL" />
      </geometry>
      <material
        name="">
        <color
          rgba="1 1 1 1" />
      </material>
    </visual>
    <collision>
      <origin
        xyz="0 0 0"
        rpy="0 0 0" />
      <geometry>
        <mesh
          filename="package://kubot25_pkgs/meshes/L_Hip_yaw_collision.STL" />
      </geometry>
    </collision>
  </link>
  <joint
    name="L_Hip_yaw_joint"
    type="revolute">
    <origin
      xyz="0.028062 0.05005 -0.077556"
      rpy="0 0 0" />
    <parent
      link="base_link" />
    <child
      link="L_Hip_yaw" />
    <axis
      xyz="0 0 -1" />
    <limit
      lower="-3.1415"
      upper="3.1415"
      effort="100.0"
      velocity="10.0" />
  </joint>
  <link
    name="L_Hip_roll">
    <inertial>
      <origin
        xyz="0.029793 5.6241E-05 -0.015766"
        rpy="0 0 0" />
      <mass
        value="0.34600887" />
      <inertia
        ixx="8.102E-05"
        ixy="5.2E-07"
        ixz="3.11E-06"
        iyy="0.00035597"
        iyz="6E-07"
        izz="0.00032885" />
    </inertial>
    <visual>
      <origin
        xyz="0 0 0"
        rpy="0 0 0" />
      <geometry>
        <mesh
          filename="package://kubot25_pkgs/meshes/L_Hip_roll.STL" />
      </geometry>
      <material
        name="">
        <color
          rgba="1 1 1 1" />
      </material>
    </visual>
    <collision>
      <origin
        xyz="0 0 0"
        rpy="0 0 0" />
      <geometry>
        <mesh
          filename="package://kubot25_pkgs/meshes/L_Hip_roll_collision.STL" />
      </geometry>
    </collision>
  </link>
  <joint
    name="L_Hip_roll_joint"
    type="revolute">
    <origin
      xyz="-0.0595 0 -0.065879"
      rpy="0 0 0" />
    <parent
      link="L_Hip_yaw" />
    <child
      link="L_Hip_roll" />
    <axis
      xyz="1 0 0" />
    <limit
      lower="-3.1415"
      upper="3.1415"
      effort="100.0"
      velocity="10.0" />
  </joint>
  <link
    name="L_Hip_pitch">
    <inertial>
      <origin
        xyz="2.1423E-06 0.00017035 -0.097401"
        rpy="0 0 0" />
      <mass
        value="0.22104" />
      <inertia
        ixx="0.00032851"
        ixy="0"
        ixz="-1E-08"
        iyy="0.00028749"
        iyz="-9.2E-07"
        izz="6.997E-05" />
    </inertial>
    <visual>
      <origin
        xyz="0 0 0"
        rpy="0 0 0" />
      <geometry>
        <mesh
          filename="package://kubot25_pkgs/meshes/L_Hip_pitch.STL" />
      </geometry>
      <material
        name="">
        <color
          rgba="1 1 1 1" />
      </material>
    </visual>
    <collision>
      <origin
        xyz="0 0 0"
        rpy="0 0 0" />
      <geometry>
        <mesh
          filename="package://kubot25_pkgs/meshes/L_Hip_pitch_collision.STL" />
      </geometry>
    </collision>
  </link>
  <joint
    name="L_Hip_pitch_joint"
    type="revolute">
    <origin
      xyz="0.0562 0 0"
      rpy="0 0 0" />
    <parent
      link="L_Hip_roll" />
    <child
      link="L_Hip_pitch" />
    <axis
      xyz="0 -1 0" />
    <limit
      lower="-3.1415"
      upper="3.1415"
      effort="100.0"
      velocity="10.0" />
  </joint>
  <link
    name="L_Knee_pitch">
    <inertial>
      <origin
        xyz="7.3413E-15 0.0001 -0.069133"
        rpy="0 0 0" />
      <mass
        value="0.04" />
      <inertia
        ixx="0.00010956"
        ixy="0"
        ixz="0"
        iyy="8.359E-05"
        iyz="0"
        izz="3.194E-05" />
    </inertial>
    <visual>
      <origin
        xyz="0 0 0"
        rpy="0 0 0" />
      <geometry>
        <mesh
          filename="package://kubot25_pkgs/meshes/L_Knee_pitch.STL" />
      </geometry>
      <material
        name="">
        <color
          rgba="1 1 1 1" />
      </material>
    </visual>
    <collision>
      <origin
        xyz="0 0 0"
        rpy="0 0 0" />
      <geometry>
        <mesh
          filename="package://kubot25_pkgs/meshes/L_Knee_pitch_collision.STL" />
      </geometry>
    </collision>
  </link>
  <joint
    name="L_Knee_pitch_joint"
    type="revolute">
    <origin
      xyz="0 0.0001 -0.14"
      rpy="0 0 0" />
    <parent
      link="L_Hip_pitch" />
    <child
      link="L_Knee_pitch" />
    <axis
      xyz="0 1 0" />
    <limit
      lower="-3.1415"
      upper="3.1415"
      effort="100.0"
      velocity="10.0" />
  </joint>
  <link
    name="L_Ankle_pitch">
    <inertial>
      <origin
        xyz="-0.026403 5.2916E-05 0.015768"
        rpy="0 0 0" />
      <mass
        value="0.3460088" />
      <inertia
        ixx="8.102E-05"
        ixy="5.5E-07"
        ixz="-3.1E-06"
        iyy="0.00035603"
        iyz="-6E-07"
        izz="0.00032891" />
    </inertial>
    <visual>
      <origin
        xyz="0 0 0"
        rpy="0 0 0" />
      <geometry>
        <mesh
          filename="package://kubot25_pkgs/meshes/L_Ankle_pitch.STL" />
      </geometry>
      <material
        name="">
        <color
          rgba="1 1 1 1" />
      </material>
    </visual>
    <collision>
      <origin
        xyz="0 0 0"
        rpy="0 0 0" />
      <geometry>
        <mesh
          filename="package://kubot25_pkgs/meshes/L_Ankle_pitch_collision.STL" />
      </geometry>
    </collision>
  </link>
  <joint
    name="L_Ankle_pitch_joint"
    type="revolute">
    <origin
      xyz="0 0 -0.142"
      rpy="0 0 0" />
    <parent
      link="L_Knee_pitch" />
    <child
      link="L_Ankle_pitch" />
    <axis
      xyz="0 1 0" />
    <limit
      lower="-3.1415"
      upper="3.1415"
      effort="100.0"
      velocity="10.0" />
  </joint>
  <link
    name="L_Ankle_roll">
    <inertial>
      <origin
        xyz="0.05891 -7.6328E-16 -0.013829"
        rpy="0 0 0" />
      <mass
        value="0.01546878" />
      <inertia
        ixx="5.03E-06"
        ixy="0"
        ixz="3.9E-07"
        iyy="1.725E-05"
        iyz="0"
        izz="1.55E-05" />
    </inertial>
    <visual>
      <origin
        xyz="0 0 0"
        rpy="0 0 0" />
      <geometry>
        <mesh
          filename="package://kubot25_pkgs/meshes/L_Ankle_roll.STL" />
      </geometry>
      <material
        name="">
        <color
          rgba="1 1 1 1" />
      </material>
    </visual>
    <collision>
      <origin
        xyz="0 0 0"
        rpy="0 0 0" />
      <geometry>
        <mesh
          filename="package://kubot25_pkgs/meshes/L_Ankle_roll_collision.STL" />
      </geometry>
    </collision>
  </link>
  <joint
    name="L_Ankle_roll_joint"
    type="revolute">
    <origin
      xyz="-0.0562 0 0"
      rpy="0 0 0" />
    <parent
      link="L_Ankle_pitch" />
    <child
      link="L_Ankle_roll" />
    <axis
      xyz="1 0 0" />
    <limit
      lower="-3.1415"
      upper="3.1415"
      effort="100.0"
      velocity="10.0" />
  </joint>
  <link
    name="L_Foot">
    <inertial>
      <origin
        xyz="0.0034202 0.027405 0.0039506"
        rpy="0 0 0" />
      <mass
        value="0.063" />
      <inertia
        ixx="6.406E-05"
        ixy="-3E-08"
        ixz="2.07E-06"
        iyy="0.00014535"
        iyz="0"
        izz="0.00020843" />
    </inertial>
    <visual>
      <origin
        xyz="0 0 0"
        rpy="0 0 0" />
      <geometry>
        <mesh
          filename="package://kubot25_pkgs/meshes/L_Foot.STL" />
      </geometry>
      <material
        name="">
        <color
          rgba="1 1 1 1" />
      </material>
    </visual>
    <collision>
      <origin
        xyz="0 0 0"
        rpy="0 0 0" />
      <geometry>
        <mesh
          filename="package://kubot25_pkgs/meshes/L_Foot_collision.STL" />
      </geometry>
    </collision>
  </link>
  <joint
    name="L_Foot_joint"
    type="fixed">
    <origin
      xyz="0.0595 -0.0001 -0.042"
      rpy="0 0 0" />
    <parent
      link="L_Ankle_roll" />
    <child
      link="L_Foot" />
    <axis
      xyz="0 0 0" />
  </joint>
  <link
    name="R_Hip_yaw">
    <inertial>
      <origin
        xyz="-0.0010223 0 -0.04111"
        rpy="0 0 0" />
      <mass
        value="0.023559" />
      <inertia
        ixx="8.7E-06"
        ixy="0"
        ixz="-7.7E-07"
        iyy="1.842E-05"
        iyz="0"
        izz="1.691E-05" />
    </inertial>
    <visual>
      <origin
        xyz="0 0 0"
        rpy="0 0 0" />
      <geometry>
        <mesh
          filename="package://kubot25_pkgs/meshes/R_Hip_yaw.STL" />
      </geometry>
      <material
        name="">
        <color
          rgba="1 1 1 1" />
      </material>
    </visual>
    <collision>
      <origin
        xyz="0 0 0"
        rpy="0 0 0" />
      <geometry>
        <mesh
          filename="package://kubot25_pkgs/meshes/R_Hip_yaw_collision.STL" />
      </geometry>
    </collision>
  </link>
  <joint
    name="R_Hip_yaw_joint"
    type="revolute">
    <origin
      xyz="0.028062 -0.04995 -0.077556"
      rpy="0 0 0" />
    <parent
      link="base_link" />
    <child
      link="R_Hip_yaw" />
    <axis
      xyz="0 0 -1" />
    <limit
      lower="-3.1415"
      upper="3.1415"
      effort="100.0"
      velocity="10.0" />
  </joint>
  <link
    name="R_Hip_roll">
    <inertial>
      <origin
        xyz="0.029797 -5.2916E-05 -0.015766"
        rpy="0 0 0" />
      <mass
        value="0.34601" />
      <inertia
        ixx="8.102E-05"
        ixy="-5.5E-07"
        ixz="3.11E-06"
        iyy="0.00035603"
        iyz="-6E-07"
        izz="0.00032891" />
    </inertial>
    <visual>
      <origin
        xyz="0 0 0"
        rpy="0 0 0" />
      <geometry>
        <mesh
          filename="package://kubot25_pkgs/meshes/R_Hip_roll.STL" />
      </geometry>
      <material
        name="">
        <color
          rgba="1 1 1 1" />
      </material>
    </visual>
    <collision>
      <origin
        xyz="0 0 0"
        rpy="0 0 0" />
      <geometry>
        <mesh
          filename="package://kubot25_pkgs/meshes/R_Hip_roll_collision.STL" />
      </geometry>
    </collision>
  </link>
  <joint
    name="R_Hip_roll_joint"
    type="revolute">
    <origin
      xyz="-0.0595 0 -0.065875"
      rpy="0 0 0" />
    <parent
      link="R_Hip_yaw" />
    <child
      link="R_Hip_roll" />
    <axis
      xyz="1 0 0" />
    <limit
      lower="-3.1415"
      upper="3.1415"
      effort="100.0"
      velocity="10.0" />
  </joint>
  <link
    name="R_Hip_pitch">
    <inertial>
      <origin
        xyz="-2.1423E-06 -0.00017035 -0.097401"
        rpy="0 0 0" />
      <mass
        value="0.22104" />
      <inertia
        ixx="0.00032851"
        ixy="0"
        ixz="1E-08"
        iyy="0.00028749"
        iyz="9.2E-07"
        izz="6.997E-05" />
    </inertial>
    <visual>
      <origin
        xyz="0 0 0"
        rpy="0 0 0" />
      <geometry>
        <mesh
          filename="package://kubot25_pkgs/meshes/R_Hip_pitch.STL" />
      </geometry>
      <material
        name="">
        <color
          rgba="1 1 1 1" />
      </material>
    </visual>
    <collision>
      <origin
        xyz="0 0 0"
        rpy="0 0 0" />
      <geometry>
        <mesh
          filename="package://kubot25_pkgs/meshes/R_Hip_pitch_collision.STL" />
      </geometry>
    </collision>
  </link>
  <joint
    name="R_Hip_pitch_joint"
    type="revolute">
    <origin
      xyz="0.0562 0 0"
      rpy="0 0 0" />
    <parent
      link="R_Hip_roll" />
    <child
      link="R_Hip_pitch" />
    <axis
      xyz="0 -1 0" />
    <limit
      lower="-3.1415"
      upper="3.1415"
      effort="100.0"
      velocity="10.0" />
  </joint>
  <link
    name="R_Knee_pitch">
    <inertial>
      <origin
        xyz="2.3592E-15 -0.0001 -0.069133"
        rpy="0 0 0" />
      <mass
        value="0.04" />
      <inertia
        ixx="0.00010956"
        ixy="0"
        ixz="0"
        iyy="8.359E-05"
        iyz="0"
        izz="3.194E-05" />
    </inertial>
    <visual>
      <origin
        xyz="0 0 0"
        rpy="0 0 0" />
      <geometry>
        <mesh
          filename="package://kubot25_pkgs/meshes/R_Knee_pitch.STL" />
      </geometry>
      <material
        name="">
        <color
          rgba="1 1 1 1" />
      </material>
    </visual>
    <collision>
      <origin
        xyz="0 0 0"
        rpy="0 0 0" />
      <geometry>
        <mesh
          filename="package://kubot25_pkgs/meshes/R_Knee_pitch_collision.STL" />
      </geometry>
    </collision>
  </link>
  <joint
    name="R_Knee_pitch_joint"
    type="revolute">
    <origin
      xyz="0 -0.0001 -0.14"
      rpy="0 0 0" />
    <parent
      link="R_Hip_pitch" />
    <child
      link="R_Knee_pitch" />
    <axis
      xyz="0 -1 0" />
    <limit
      lower="-3.1415"
      upper="3.1415"
      effort="100.0"
      velocity="10.0" />
  </joint>
  <link
    name="R_Ankle_pitch">
    <inertial>
      <origin
        xyz="-0.026407 -5.6241E-05 0.015768"
        rpy="0 0 0" />
      <mass
        value="0.34600887" />
      <inertia
        ixx="8.102E-05"
        ixy="-5.2E-07"
        ixz="-3.09E-06"
        iyy="0.00035597"
        iyz="6E-07"
        izz="0.00032885" />
    </inertial>
    <visual>
      <origin
        xyz="0 0 0"
        rpy="0 0 0" />
      <geometry>
        <mesh
          filename="package://kubot25_pkgs/meshes/R_Ankle_pitch.STL" />
      </geometry>
      <material
        name="">
        <color
          rgba="1 1 1 1" />
      </material>
    </visual>
    <collision>
      <origin
        xyz="0 0 0"
        rpy="0 0 0" />
      <geometry>
        <mesh
          filename="package://kubot25_pkgs/meshes/R_Ankle_pitch_collision.STL" />
      </geometry>
    </collision>
  </link>
  <joint
    name="R_Ankle_pitch_joint"
    type="revolute">
    <origin
      xyz="0 0 -0.142"
      rpy="0 0 0" />
    <parent
      link="R_Knee_pitch" />
    <child
      link="R_Ankle_pitch" />
    <axis
      xyz="0 -1 0" />
    <limit
      lower="-3.1415"
      upper="3.1415"
      effort="100.0"
      velocity="10.0" />
  </joint>
  <link
    name="R_Ankle_roll">
    <inertial>
      <origin
        xyz="0.05891 1.0426E-14 -0.013829"
        rpy="0 0 0" />
      <mass
        value="0.01546878" />
      <inertia
        ixx="5.03E-06"
        ixy="0"
        ixz="3.9E-07"
        iyy="1.725E-05"
        iyz="0"
        izz="1.55E-05" />
    </inertial>
    <visual>
      <origin
        xyz="0 0 0"
        rpy="0 0 0" />
      <geometry>
        <mesh
          filename="package://kubot25_pkgs/meshes/R_Ankle_roll.STL" />
      </geometry>
      <material
        name="">
        <color
          rgba="1 1 1 1" />
      </material>
    </visual>
    <collision>
      <origin
        xyz="0 0 0"
        rpy="0 0 0" />
      <geometry>
        <mesh
          filename="package://kubot25_pkgs/meshes/R_Ankle_roll_collision.STL" />
      </geometry>
    </collision>
  </link>
  <joint
    name="R_Ankle_roll_joint"
    type="revolute">
    <origin
      xyz="-0.0562 0 0"
      rpy="0 0 0" />
    <parent
      link="R_Ankle_pitch" />
    <child
      link="R_Ankle_roll" />
    <axis
      xyz="1 0 0" />
    <limit
      lower="-3.1415"
      upper="3.1415"
      effort="100.0"
      velocity="10.0" />
  </joint>
  <link
    name="R_Foot">
    <inertial>
      <origin
        xyz="0.0034202 -0.1274 0.0039546"
        rpy="0 0 0" />
      <mass
        value="0.063" />
      <inertia
        ixx="6.406E-05"
        ixy="3E-08"
        ixz="2.07E-06"
        iyy="0.00014535"
        iyz="0"
        izz="0.00020843" />
    </inertial>
    <visual>
      <origin
        xyz="0 0 0"
        rpy="0 0 0" />
      <geometry>
        <mesh
          filename="package://kubot25_pkgs/meshes/R_Foot.STL" />
      </geometry>
      <material
        name="">
        <color
          rgba="1 1 1 1" />
      </material>
    </visual>
    <collision>
      <origin
        xyz="0 0 0"
        rpy="0 0 0" />
      <geometry>
        <mesh
          filename="package://kubot25_pkgs/meshes/R_Foot_collision.STL" />
      </geometry>
    </collision>
  </link>
  <joint
    name="R_Foot_joint"
    type="fixed">
    <origin
      xyz="0.0595 0.0001 -0.042004"
      rpy="0 0 0" />
    <parent
      link="R_Ankle_roll" />
    <child
      link="R_Foot" />
    <axis
      xyz="0 0 0" />
  </joint>
  
  <ros2_control name="GazeboSystem" type="system">
    <hardware>
      <plugin>gazebo_ros2_control/GazeboSystem</plugin>
    </hardware>
    
    <joint name="Neck_yaw_joint">
      <command_interface name="position"/>
      <state_interface name="position"/>
      <state_interface name="velocity"/>
    </joint>
    <joint name="Head_pitch_joint">
      <command_interface name="position"/>
      <state_interface name="position"/>
      <state_interface name="velocity"/>
    </joint>
    
    <joint name="L_Shoulder_pitch_joint">
      <command_interface name="position"/>
      <state_interface name="position"/>
      <state_interface name="velocity"/>
    </joint>
    <joint name="L_Arm_roll_joint">
      <command_interface name="position"/>
      <state_interface name="position"/>
      <state_interface name="velocity"/>
    </joint>
    <joint name="L_Hand_pitch_joint">
      <command_interface name="position"/>
      <state_interface name="position"/>
      <state_interface name="velocity"/>
    </joint>

    <joint name="R_Shoulder_pitch_joint">
      <command_interface name="position"/>
      <state_interface name="position"/>
      <state_interface name="velocity"/>
    </joint>
    <joint name="R_Arm_roll_joint">
      <command_interface name="position"/>
      <state_interface name="position"/>
      <state_interface name="velocity"/>
    </joint>
    <joint name="R_Hand_pitch_joint">
      <command_interface name="position"/>
      <state_interface name="position"/>
      <state_interface name="velocity"/>
    </joint>

    <joint name="L_Hip_yaw_joint">
      <command_interface name="position"/>
      <state_interface name="position"/>
      <state_interface name="velocity"/>
    </joint>
    <joint name="L_Hip_roll_joint">
      <command_interface name="position"/>
      <state_interface name="position"/>
      <state_interface name="velocity"/>
    </joint>
    <joint name="L_Hip_pitch_joint">
      <command_interface name="position"/>
      <state_interface name="position"/>
      <state_interface name="velocity"/>
    </joint>
    <joint name="L_Knee_pitch_joint">
      <command_interface name="position"/>
      <state_interface name="position"/>
      <state_interface name="velocity"/>
    </joint>
    <joint name="L_Ankle_pitch_joint">
      <command_interface name="position"/>
      <state_interface name="position"/>
      <state_interface name="velocity"/>
    </joint>
    <joint name="L_Ankle_roll_joint">
      <command_interface name="position"/>
      <state_interface name="position"/>
      <state_interface name="velocity"/>
    </joint>

    <joint name="R_Hip_yaw_joint">
      <command_interface name="position"/>
      <state_interface name="position"/>
      <state_interface name="velocity"/>
    </joint>
    <joint name="R_Hip_roll_joint">
      <command_interface name="position"/>
      <state_interface name="position"/>
      <state_interface name="velocity"/>
    </joint>
    <joint name="R_Hip_pitch_joint">
      <command_interface name="position"/>
      <state_interface name="position"/>
      <state_interface name="velocity"/>
    </joint>
    <joint name="R_Knee_pitch_joint">
      <command_interface name="position"/>
      <state_interface name="position"/>
      <state_interface name="velocity"/>
    </joint>
    <joint name="R_Ankle_pitch_joint">
      <command_interface name="position"/>
      <state_interface name="position"/>
      <state_interface name="velocity"/>
    </joint>
    <joint name="R_Ankle_roll_joint">
      <command_interface name="position"/>
      <state_interface name="position"/>
      <state_interface name="velocity"/>
    </joint>
  </ros2_control>

  <gazebo>
    <plugin filename="libgazebo_ros2_control.so" name="gazebo_ros2_control">
      <parameters>$(find kubot25_pkgs)/config/kubot25_controllers.yaml</parameters>
    </plugin>
  </gazebo>
  <gazebo reference="base_link">
    <visual>
      <material>
        <ambient>0.2 0.2 0.2 1.0</ambient>
        <diffuse>0.3 0.3 0.3 1.0</diffuse>
      </material>
    </visual>
  </gazebo>
  
  <gazebo reference="Neck_yaw">
    <visual>
      <material>
        <ambient>0.1 0.1 0.1 1.0</ambient>
        <diffuse>0.1 0.1 0.1 1.0</diffuse>
      </material>
    </visual>
  </gazebo>

  <gazebo reference="Head_pitch">
    <visual>
      <material>
        <ambient>0.8 0.4 0.0 1.0</ambient>
        <diffuse>0.9 0.5 0.0 1.0</diffuse>
      </material>
    </visual>
  </gazebo>
  
  <gazebo reference="L_Shoulder_pitch">
    <visual>
      <material>
        <ambient>0.1 0.2 0.5 1.0</ambient>
        <diffuse>0.2 0.3 0.6 1.0</diffuse>
      </material>
    </visual>
  </gazebo>
  
  <gazebo reference="R_Shoulder_pitch">
    <visual>
      <material>
        <ambient>0.1 0.2 0.5 1.0</ambient>
        <diffuse>0.2 0.3 0.6 1.0</diffuse>
      </material>
    </visual>
  </gazebo>
</robot>

